Workbook
Name Gen_Ind: 'Main Data'!$AE:$AE
Name Latestmonth: Transpose!$DW:$DW
Name May: Transpose!$DW:$DW
Name Month: 'Main Data'!$C:$C
Name Name: Transpose!$DW:$DW
Name Sector: 'Main Data'!$A:$A
Name Year: 'Main Data'!$B:$B

Sheet Backup
A1: Sector | B1: Year | C1: Month | D1: Cereals and products | E1: Meat and fish | F1: Egg | G1: Milk and products | H1: Oils and fats | I1: Fruits | J1: Vegetables | K1: Pulses and products | L1: Sugar and Confectionery | M1: Spices | N1: Non-alcoholic beverages | O1: Prepared meals, snacks, sweets etc. | P1: Food and beverages | Q1: Pan, tobacco and intoxicants | R1: Clothing | S1: Footwear | T1: Clothing and footwear | U1: Housing | V1: Fuel and light | W1: Household goods and services | X1: Health | Y1: Transport and communication | Z1: Recreation and amusement | AA1: Education | AB1: Personal care and effects | AC1: Miscellaneous | AD1: General index
A2: Rural | B2: 2013 | C2: January | D2: 107.5 | E2: 106.3 | F2: 108.1 | G2: 104.9 | H2: 106.1 | I2: 103.9 | J2: 101.9 | K2: 106.1 | L2: 106.8 | M2: 103.1 | N2: 104.8 | O2: 106.7 | P2: 105.5 | Q2: 105.1 | R2: 106.5 | S2: 105.8 | T2: 106.4 | U2: NA | V2: 105.5 | W2: 104.8 | X2: 104 | Y2: 103.3 | Z2: 103.4 | AA2: 103.8 | AB2: 104.7 | AC2: 104 | AD2: 105.1
A3: Urban | B3: 2013 | C3: January | D3: 110.5 | E3: 109.1 | F3: 113 | G3: 103.6 | H3: 103.4 | I3: 102.3 | J3: 102.9 | K3: 105.8 | L3: 105.1 | M3: 101.8 | N3: 105.1 | O3: 107.9 | P3: 105.9 | Q3: 105.2 | R3: 105.9 | S3: 105 | T3: 105.8 | U3: 100.3 | V3: 105.4 | W3: 104.8 | X3: 104.1 | Y3: 103.2 | Z3: 102.9 | AA3: 103.5 | AB3: 104.3 | AC3: 103.7 | AD3: 104
A4: Rural+Urban | B4: 2013 | C4: January | D4: 108.4 | E4: 107.3 | F4: 110 | G4: 104.4 | H4: 105.1 | I4: 103.2 | J4: 102.2 | K4: 106 | L4: 106.2 | M4: 102.7 | N4: 104.9 | O4: 107.3 | P4: 105.6 | Q4: 105.1 | R4: 106.3 | S4: 105.5 | T4: 106.2 | U4: 100.3 | V4: 105.5 | W4: 104.8 | X4: 104 | Y4: 103.2 | Z4: 103.1 | AA4: 103.6 | AB4: 104.5 | AC4: 103.9 | AD4: 104.6
A5: Rural | B5: 2013 | C5: February | D5: 109.2 | E5: 108.7 | F5: 110.2 | G5: 105.4 | H5: 106.7 | I5: 104 | J5: 102.4 | K5: 105.9 | L5: 105.7 | M5: 103.1 | N5: 105.1 | O5: 107.7 | P5: 106.3 | Q5: 105.6 | R5: 107.1 | S5: 106.3 | T5: 107 | U5: NA | V5: 106.2 | W5: 105.2 | X5: 104.4 | Y5: 103.9 | Z5: 104 | AA5: 104.1 | AB5: 104.6 | AC5: 104.4 | AD5: 105.8
A6: Urban | B6: 2013 | C6: February | D6: 112.9 | E6: 112.9 | F6: 116.9 | G6: 104 | H6: 103.5 | I6: 103.1 | J6: 104.9 | K6: 104.1 | L6: 103.8 | M6: 102.3 | N6: 106 | O6: 109 | P6: 107.2 | Q6: 106 | R6: 106.6 | S6: 105.5 | T6: 106.4 | U6: 100.4 | V6: 105.7 | W6: 105.2 | X6: 104.7 | Y6: 104.4 | Z6: 103.3 | AA6: 103.7 | AB6: 104.3 | AC6: 104.3 | AD6: 104.7
A7: Rural+Urban | B7: 2013 | C7: February | D7: 110.4 | E7: 110.2 | F7: 112.8 | G7: 104.9 | H7: 105.5 | I7: 103.6 | J7: 103.2 | K7: 105.3 | L7: 105.1 | M7: 102.8 | N7: 105.5 | O7: 108.3 | P7: 106.6 | Q7: 105.7 | R7: 106.9 | S7: 106 | T7: 106.8 | U7: 100.4 | V7: 106 | W7: 105.2 | X7: 104.5 | Y7: 104.2 | Z7: 103.6 | AA7: 103.9 | AB7: 104.5 | AC7: 104.4 | AD7: 105.3
A8: Rural | B8: 2013 | C8: March | D8: 110.2 | E8: 108.8 | F8: 109.9 | G8: 105.6 | H8: 106.2 | I8: 105.7 | J8: 101.4 | K8: 105.7 | L8: 105 | M8: 103.3 | N8: 105.6 | O8: 108.2 | P8: 106.6 | Q8: 106.5 | R8: 107.6 | S8: 106.8 | T8: 107.5 | U8: NA | V8: 106.1 | W8: 105.6 | X8: 104.7 | Y8: 104.6 | Z8: 104 | AA8: 104.3 | AB8: 104.3 | AC8: 104.6 | AD8: 106
A9: Urban | B9: 2013 | C9: March | D9: 113.9 | E9: 111.4 | F9: 113.2 | G9: 104.3 | H9: 102.7 | I9: 104.9 | J9: 103.8 | K9: 103.5 | L9: 102.6 | M9: 102.4 | N9: 107 | O9: 109.8 | P9: 107.3 | Q9: 106.8 | R9: 107.2 | S9: 106 | T9: 107 | U9: 100.4 | V9: 106 | W9: 105.7 | X9: 105.2 | Y9: 105.5 | Z9: 103.5 | AA9: 103.8 | AB9: 104.2 | AC9: 104.9 | AD9: 105
A10: Rural+Urban | B10: 2013 | C10: March | D10: 111.4 | E10: 109.7 | F10: 111.2 | G10: 105.1 | H10: 104.9 | I10: 105.3 | J10: 102.2 | K10: 105 | L10: 104.2 | M10: 103 | N10: 106.2 | O10: 108.9 | P10: 106.9 | Q10: 106.6 | R10: 107.4 | S10: 106.5 | T10: 107.3 | U10: 100.4 | V10: 106.1 | W10: 105.6 | X10: 104.9 | Y10: 105.1 | Z10: 103.7 | AA10: 104 | AB10: 104.3 | AC10: 104.7 | AD10: 105.5
A11: Rural | B11: 2013 | C11: April | D11: 110.2 | E11: 109.5 | F11: 106.9 | G11: 106.3 | H11: 105.7 | I11: 108.3 | J11: 103.4 | K11: 105.7 | L11: 104.2 | M11: 103.2 | N11: 106.5 | O11: 108.8 | P11: 107.1 | Q11: 107.1 | R11: 108.1 | S11: 107.4 | T11: 108 | U11: NA | V11: 106.5 | W11: 106.1 | X11: 105.1 | Y11: 104.4 | Z11: 104.5 | AA11: 104.8 | AB11: 102.7 | AC11: 104.6 | AD11: 106.4
A12: Urban | B12: 2013 | C12: April | D12: 114.6 | E12: 113.4 | F12: 106 | G12: 104.7 | H12: 102.1 | I12: 109.5 | J12: 109.7 | K12: 104.6 | L12: 102 | M12: 103.5 | N12: 108.2 | O12: 110.6 | P12: 108.8 | Q12: 108.5 | R12: 107.9 | S12: 106.4 | T12: 107.7 | U12: 100.5 | V12: 106.4 | W12: 106.5 | X12: 105.7 | Y12: 105 | Z12: 104 | AA12: 105.2 | AB12: 103.2 | AC12: 105.1 | AD12: 105.7
A13: Rural+Urban | B13: 2013 | C13: April | D13: 111.6 | E13: 110.9 | F13: 106.6 | G13: 105.7 | H13: 104.4 | I13: 108.9 | J13: 105.5 | K13: 105.3 | L13: 103.5 | M13: 103.3 | N13: 107.2 | O13: 109.6 | P13: 107.7 | Q13: 107.5 | R13: 108 | S13: 107 | T13: 107.9 | U13: 100.5 | V13: 106.5 | W13: 106.3 | X13: 105.3 | Y13: 104.7 | Z13: 104.2 | AA13: 105 | AB13: 102.9 | AC13: 104.8 | AD13: 106.1
A14: Rural | B14: 2013 | C14: May | D14: 110.9 | E14: 109.8 | F14: 105.9 | G14: 107.5 | H14: 105.3 | I14: 108.1 | J14: 107.3 | K14: 106.1 | L14: 103.7 | M14: 104 | N14: 107.4 | O14: 109.9 | P14: 108.1 | Q14: 108.1 | R14: 108.8 | S14: 107.9 | T14: 108.6 | U14: NA | V14: 107.5 | W14: 106.8 | X14: 105.7 | Y14: 104.1 | Z14: 105 | AA14: 105.5 | AB14: 102.1 | AC14: 104.8 | AD14: 107.2
A15: Urban | B15: 2013 | C15: May | D15: 115.4 | E15: 114.2 | F15: 102.7 | G15: 105.5 | H15: 101.5 | I15: 110.6 | J15: 123.7 | K15: 105.2 | L15: 101.9 | M15: 105 | N15: 109.1 | O15: 111.3 | P15: 111.1 | Q15: 109.8 | R15: 108.5 | S15: 106.7 | T15: 108.3 | U15: 100.5 | V15: 107.2 | W15: 107.1 | X15: 106.2 | Y15: 103.9 | Z15: 104.6 | AA15: 105.7 | AB15: 102.6 | AC15: 104.9 | AD15: 106.6
A16: Rural+Urban | B16: 2013 | C16: May | D16: 112.3 | E16: 111.3 | F16: 104.7 | G16: 106.8 | H16: 103.9 | I16: 109.3 | J16: 112.9 | K16: 105.8 | L16: 103.1 | M16: 104.3 | N16: 108.1 | O16: 110.5 | P16: 109.2 | Q16: 108.6 | R16: 108.7 | S16: 107.4 | T16: 108.5 | U16: 100.5 | V16: 107.4 | W16: 106.9 | X16: 105.9 | Y16: 104 | Z16: 104.8 | AA16: 105.6 | AB16: 102.3 | AC16: 104.8 | AD16: 106.9
A17: Rural | B17: 2013 | C17: June | D17: 112.3 | E17: 112.1 | F17: 108.1 | G17: 108.3 | H17: 105.9 | I17: 109.2 | J17: 118 | K17: 106.8 | L17: 104.1 | M17: 105.4 | N17: 108.2 | O17: 111 | P17: 110.6 | Q17: 109 | R17: 109.7 | S17: 108.8 | T17: 109.5 | U17: NA | V17: 108.5 | W17: 107.5 | X17: 106.3 | Y17: 105 | Z17: 105.6 | AA17: 106.5 | AB17: 102.5 | AC17: 105.5 | AD17: 108.9
A18: Urban | B18: 2013 | C18: June | D18: 117 | E18: 120.1 | F18: 112.5 | G18: 107.3 | H18: 101.3 | I18: 112.4 | J18: 143.6 | K18: 105.4 | L18: 101.4 | M18: 106.4 | N18: 110 | O18: 112.2 | P18: 115 | Q18: 110.9 | R18: 109.2 | S18: 107.2 | T18: 108.9 | U18: 106.6 | V18: 108 | W18: 107.7 | X18: 106.5 | Y18: 105.2 | Z18: 105.2 | AA18: 108.1 | AB18: 103.3 | AC18: 106.1 | AD18: 109.7
A19: Rural+Urban | B19: 2013 | C19: June | D19: 113.8 | E19: 114.9 | F19: 109.8 | G19: 107.9 | H19: 104.2 | I19: 110.7 | J19: 126.7 | K19: 106.3 | L19: 103.2 | M19: 105.7 | N19: 109 | O19: 111.6 | P19: 112.2 | Q19: 109.5 | R19: 109.5 | S19: 108.1 | T19: 109.3 | U19: 106.6 | V19: 108.3 | W19: 107.6 | X19: 106.4 | Y19: 105.1 | Z19: 105.4 | AA19: 107.4 | AB19: 102.8 | AC19: 105.8 | AD19: 109.3
A20: Rural | B20: 2013 | C20: July | D20: 113.4 | E20: 114.9 | F20: 110.5 | G20: 109.3 | H20: 106.2 | I20: 110.3 | J20: 129.2 | K20: 107.1 | L20: 104.3 | M20: 106.4 | N20: 109.1 | O20: 112.1 | P20: 113.1 | Q20: 109.8 | R20: 110.5 | S20: 109.5 | T20: 110.3 | U20: NA | V20: 109.5 | W20: 108.3 | X20: 106.9 | Y20: 106.8 | Z20: 106.4 | AA20: 107.8 | AB20: 102.5 | AC20: 106.5 | AD20: 110.7
A21: Urban | B21: 2013 | C21: July | D21: 117.8 | E21: 119.2 | F21: 114 | G21: 108.3 | H21: 101.1 | I21: 113.2 | J21: 160.9 | K21: 105.1 | L21: 101.3 | M21: 107.5 | N21: 110.4 | O21: 113.1 | P21: 117.5 | Q21: 111.7 | R21: 109.8 | S21: 107.8 | T21: 109.5 | U21: 107.7 | V21: 108.6 | W21: 108.1 | X21: 107.1 | Y21: 107.3 | Z21: 105.9 | AA21: 110.1 | AB21: 103.2 | AC21: 107.3 | AD21: 111.4
A22: Rural+Urban | B22: 2013 | C22: July | D22: 114.8 | E22: 116.4 | F22: 111.9 | G22: 108.9 | H22: 104.3 | I22: 111.7 | J22: 140 | K22: 106.4 | L22: 103.3 | M22: 106.8 | N22: 109.6 | O22: 112.6 | P22: 114.7 | Q22: 110.3 | R22: 110.2 | S22: 108.8 | T22: 110 | U22: 107.7 | V22: 109.2 | W22: 108.2 | X22: 107 | Y22: 107.1 | Z22: 106.1 | AA22: 109.1 | AB22: 102.8 | AC22: 106.9 | AD22: 111
A23: Rural | B23: 2013 | C23: August | D23: 114.3 | E23: 115.4 | F23: 111.1 | G23: 110 | H23: 106.4 | I23: 110.8 | J23: 138.9 | K23: 107.4 | L23: 104.1 | M23: 106.9 | N23: 109.7 | O23: 112.6 | P23: 114.9 | Q23: 110.7 | R23: 111.3 | S23: 110.2 | T23: 111.1 | U23: NA | V23: 109.9 | W23: 108.7 | X23: 107.5 | Y23: 107.8 | Z23: 106.8 | AA23: 108.7 | AB23: 105 | AC23: 107.5 | AD23: 112.1
A24: Urban | B24: 2013 | C24: August | D24: 118.3 | E24: 120.4 | F24: 112.7 | G24: 108.9 | H24: 101.1 | I24: 108.7 | J24: 177 | K24: 104.7 | L24: 101 | M24: 108.5 | N24: 110.9 | O24: 114.3 | P24: 119.6 | Q24: 112.4 | R24: 110.6 | S24: 108.3 | T24: 110.2 | U24: 108.9 | V24: 109.3 | W24: 108.7 | X24: 107.6 | Y24: 108.1 | Z24: 106.5 | AA24: 110.8 | AB24: 106 | AC24: 108.3 | AD24: 112.7
A25: Rural+Urban | B25: 2013 | C25: August | D25: 115.6 | E25: 117.2 | F25: 111.7 | G25: 109.6 | H25: 104.5 | I25: 109.8 | J25: 151.8 | K25: 106.5 | L25: 103.1 | M25: 107.4 | N25: 110.2 | O25: 113.4 | P25: 116.6 | Q25: 111.2 | R25: 111 | S25: 109.4 | T25: 110.7 | U25: 108.9 | V25: 109.7 | W25: 108.7 | X25: 107.5 | Y25: 108 | Z25: 106.6 | AA25: 109.9 | AB25: 105.4 | AC25: 107.9 | AD25: 112.4
A26: Rural | B26: 2013 | C26: September | D26: 115.4 | E26: 115.7 | F26: 111.7 | G26: 111 | H26: 107.4 | I26: 110.9 | J26: 154 | K26: 108.1 | L26: 104.2 | M26: 107.9 | N26: 110.4 | O26: 114 | P26: 117.8 | Q26: 111.7 | R26: 112.7 | S26: 111.4 | T26: 112.5 | U26: NA | V26: 111.1 | W26: 109.6 | X26: 108.3 | Y26: 109.3 | Z26: 107.7 | AA26: 109.8 | AB26: 106.7 | AC26: 108.7 | AD26: 114.2
A27: Urban | B27: 2013 | C27: September | D27: 118.6 | E27: 119.1 | F27: 113.2 | G27: 109.6 | H27: 101.7 | I27: 103.2 | J27: 174.3 | K27: 105.1 | L27: 100.8 | M27: 109.1 | N27: 111.1 | O27: 115.4 | P27: 119.2 | Q27: 112.9 | R27: 111.4 | S27: 109 | T27: 111.1 | U27: 109.7 | V27: 109.5 | W27: 109.6 | X27: 107.9 | Y27: 110.4 | Z27: 107.4 | AA27: 111.2 | AB27: 106.9 | AC27: 109.4 | AD27: 113.2
A28: Rural+Urban | B28: 2013 | C28: September | D28: 116.4 | E28: 116.9 | F28: 112.3 | G28: 110.5 | H28: 105.3 | I28: 107.3 | J28: 160.9 | K28: 107.1 | L28: 103.1 | M28: 108.3 | N28: 110.7 | O28: 114.6 | P28: 118.3 | Q28: 112 | R28: 112.2 | S28: 110.4 | T28: 111.9 | U28: 109.7 | V28: 110.5 | W28: 109.6 | X28: 108.1 | Y28: 109.9 | Z28: 107.5 | AA28: 110.6 | AB28: 106.8 | AC28: 109 | AD28: 113.7
A29: Rural | B29: 2013 | C29: October | D29: 116.3 | E29: 115.4 | F29: 112.6 | G29: 111.7 | H29: 107.7 | I29: 113.2 | J29: 164.9 | K29: 108.3 | L29: 103.9 | M29: 108.2 | N29: 111.1 | O29: 114.9 | P29: 119.8 | Q29: 112.2 | R29: 113.6 | S29: 112.3 | T29: 113.4 | U29: NA | V29: 111.6 | W29: 110.4 | X29: 108.9 | Y29: 109.3 | Z29: 108.3 | AA29: 110.2 | AB29: 107.5 | AC29: 109.1 | AD29: 115.5
A30: Urban | B30: 2013 | C30: October | D30: 118.9 | E30: 118.1 | F30: 114.5 | G30: 110.4 | H30: 102.3 | I30: 106.2 | J30: 183.5 | K30: 105.3 | L30: 100.2 | M30: 109.6 | N30: 111.4 | O30: 116 | P30: 120.8 | Q30: 113.5 | R30: 112.5 | S30: 109.7 | T30: 112 | U30: 110.5 | V30: 109.7 | W30: 110.2 | X30: 108.2 | Y30: 109.7 | Z30: 108 | AA30: 111.3 | AB30: 107.3 | AC30: 109.4 | AD30: 114
A31: Rural+Urban | B31: 2013 | C31: October | D31: 117.1 | E31: 116.3 | F31: 113.3 | G31: 111.2 | H31: 105.7 | I31: 109.9 | J31: 171.2 | K31: 107.3 | L31: 102.7 | M31: 108.7 | N31: 111.2 | O31: 115.4 | P31: 120.2 | Q31: 112.5 | R31: 113.2 | S31: 111.2 | T31: 112.8 | U31: 110.5 | V31: 110.9 | W31: 110.3 | X31: 108.6 | Y31: 109.5 | Z31: 108.1 | AA31: 110.8 | AB31: 107.4 | AC31: 109.2 | AD31: 114.8
A32: Rural | B32: 2013 | C32: November | D32: 117.3 | E32: 114.9 | F32: 116.2 | G32: 112.8 | H32: 108.9 | I32: 116.6 | J32: 178.1 | K32: 109.1 | L32: 103.6 | M32: 109 | N32: 111.8 | O32: 116 | P32: 122.5 | Q32: 112.8 | R32: 114.6 | S32: 113.1 | T32: 114.4 | U32: NA | V32: 112.6 | W32: 111.3 | X32: 109.7 | Y32: 109.6 | Z32: 108.7 | AA32: 111 | AB32: 108.2 | AC32: 109.8 | AD32: 117.4
A33: Urban | B33: 2013 | C33: November | D33: 119.8 | E33: 116.3 | F33: 122.6 | G33: 112 | H33: 103.2 | I33: 110 | J33: 192.8 | K33: 106.3 | L33: 99.5 | M33: 110.3 | N33: 111.8 | O33: 117.1 | P33: 122.9 | Q33: 114.1 | R33: 113.5 | S33: 110.3 | T33: 113 | U33: 111.1 | V33: 110 | W33: 110.9 | X33: 108.6 | Y33: 109.5 | Z33: 108.5 | AA33: 111.3 | AB33: 107.9 | AC33: 109.6 | AD33: 115
A34: Rural+Urban | B34: 2013 | C34: November | D34: 118.1 | E34: 115.4 | F34: 118.7 | G34: 112.5 | H34: 106.8 | I34: 113.5 | J34: 183.1 | K34: 108.2 | L34: 102.2 | M34: 109.4 | N34: 111.8 | O34: 116.5 | P34: 122.6 | Q34: 113.1 | R34: 114.2 | S34: 111.9 | T34: 113.8 | U34: 111.1 | V34: 111.6 | W34: 111.1 | X34: 109.3 | Y34: 109.5 | Z34: 108.6 | AA34: 111.2 | AB34: 108.1 | AC34: 109.7 | AD34: 116.3
A35: Rural | B35: 2013 | C35: December | D35: 118.4 | E35: 115.9 | F35: 120.4 | G35: 113.8 | H35: 109.5 | I35: 115.5 | J35: 145.7 | K35: 109.5 | L35: 102.9 | M35: 109.8 | N35: 112.1 | O35: 116.8 | P35: 118.7 | Q35: 113.6 | R35: 115.8 | S35: 114 | T35: 115.5 | U35: NA | V35: 112.8 | W35: 112.1 | X35: 110.1 | Y35: 109.9 | Z35: 109.2 | AA35: 111.6 | AB35: 108.1 | AC35: 110.1 | AD35: 115.5
A36: Urban | B36: 2013 | C36: December | D36: 120.5 | E36: 118.1 | F36: 128.5 | G36: 112.8 | H36: 103.4 | I36: 110.7 | J36: 144.8 | K36: 107.1 | L36: 98.6 | M36: 111.9 | N36: 112.1 | O36: 118.1 | P36: 117.8 | Q36: 115 | R36: 114.2 | S36: 110.9 | T36: 113.7 | U36: 110.7 | V36: 110.4 | W36: 111.3 | X36: 109 | Y36: 109.7 | Z36: 108.9 | AA36: 111.4 | AB36: 107.7 | AC36: 109.8 | AD36: 113.3
A37: Rural+Urban | B37: 2013 | C37: December | D37: 119.1 | E37: 116.7 | F37: 123.5 | G37: 113.4 | H37: 107.3 | I37: 113.3 | J37: 145.4 | K37: 108.7 | L37: 101.5 | M37: 110.5 | N37: 112.1 | O37: 117.4 | P37: 118.4 | Q37: 114 | R37: 115.2 | S37: 112.7 | T37: 114.8 | U37: 110.7 | V37: 111.9 | W37: 111.7 | X37: 109.7 | Y37: 109.8 | Z37: 109 | AA37: 111.5 | AB37: 107.9 | AC37: 110 | AD37: 114.5
A38: Rural | B38: 2014 | C38: January | D38: 118.9 | E38: 117.1 | F38: 120.5 | G38: 114.4 | H38: 109 | I38: 115.5 | J38: 123.9 | K38: 109.6 | L38: 101.8 | M38: 110.2 | N38: 112.4 | O38: 117.3 | P38: 116 | Q38: 114 | R38: 116.5 | S38: 114.5 | T38: 116.2 | U38: NA | V38: 113 | W38: 112.6 | X38: 110.6 | Y38: 110.5 | Z38: 109.6 | AA38: 111.8 | AB38: 108.3 | AC38: 110.6 | AD38: 114.2
A39: Urban | B39: 2014 | C39: January | D39: 121.2 | E39: 122 | F39: 129.9 | G39: 113.6 | H39: 102.9 | I39: 112.1 | J39: 118.9 | K39: 107.5 | L39: 96.9 | M39: 112.7 | N39: 112.1 | O39: 119 | P39: 115.5 | Q39: 115.7 | R39: 114.8 | S39: 111.3 | T39: 114.3 | U39: 111.6 | V39: 111 | W39: 111.9 | X39: 109.7 | Y39: 110.8 | Z39: 109.8 | AA39: 111.5 | AB39: 108 | AC39: 110.5 | AD39: 112.9
A40: Rural+Urban | B40: 2014 | C40: January | D40: 119.6 | E40: 118.8 | F40: 124.1 | G40: 114.1 | H40: 106.8 | I40: 113.9 | J40: 122.2 | K40: 108.9 | L40: 100.2 | M40: 111 | N40: 112.3 | O40: 118.1 | P40: 115.8 | Q40: 114.5 | R40: 115.8 | S40: 113.2 | T40: 115.4 | U40: 111.6 | V40: 112.2 | W40: 112.3 | X40: 110.3 | Y40: 110.7 | Z40: 109.7 | AA40: 111.6 | AB40: 108.2 | AC40: 110.6 | AD40: 113.6
...

Sheet Broader Categories
A1: Category | B1: Broader Category
A2: Cereals and products | B2: Food
A3: Meat and fish | B3: Food
A4: Egg | B4: Food
A5: Milk and products | B5: Food
A6: Oils and fats | B6: Food
A7: Fruits | B7: Food
A8: Vegetables | B8: Food
A9: Pulses and products | B9: Food
A10: Sugar and Confectionery | B10: Food
A11: Spices | B11: Food
A12: Non-alcoholic beverages | B12: Food
... A28: General index | B28: Does not come under any category

Sheet Main Data
A1: Sector | B1: Year | C1: Month | D1: Year - Month | E1: Cereals and products | F1: Meat and fish | G1: Egg | H1: Milk and products | I1: Oils and fats | J1: Fruits | K1: Vegetables | L1: Pulses and products | M1: Sugar and Confectionery | N1: Spices | O1: Non-alcoholic beverages | P1: Prepared meals, snacks, sweets etc. | Q1: Food and beverages | R1: Pan, tobacco and intoxicants | S1: Clothing | T1: Footwear | U1: Clothing and footwear | V1: Housing | W1: Fuel and light | X1: Household goods and services | Y1: Health | Z1: Transport and communication | AA1: Recreation and amusement | AB1: Education | AC1: Personal care and effects | AD1: Miscellaneous | AE1: General index | AF1: Food | AG1: Apparels | AH1: Home | AI1: Health Care | AJ1: Transport | AK1: Recreation | AL1: Education Index
A2: Rural | B2: 2013 | C2: January | D2: =B2 & " - " & C2 -> 2013 - January | E2: 107.5 | F2: 106.3 | G2: 108.1 | H2: 104.9 | I2: 106.1 | J2: 103.9 | K2: 101.9 | L2: 106.1 | M2: 106.8 | N2: 103.1 | O2: 104.8 | P2: 106.7 | Q2: 105.5 | R2: 105.1 | S2: 106.5 | T2: 105.8 | U2: 106.4 | V2: NA | W2: 105.5 | X2: 104.8 | Y2: 104 | Z2: 103.3 | AA2: 103.4 | AB2: 103.8 | AC2: 104.7 | AD2: 104 | AE2: 105.1 | AF2: =SUM(E2:R2) -> 1476.8 | AG2: =SUM(S2:U2) -> 318.7 | AH2: =SUM(V2:X2) -> 210.3 | AI2: =SUM(Y2,AC2) -> 208.7 | AJ2: =SUM(Z2) -> 103.3 | AK2: =SUM(AA2) -> 103.4 | AL2: =SUM(AB2) -> 103.8
A3: Urban | B3: 2013 | C3: January | D3: =B3 & " - " & C3 -> 2013 - January | E3: 110.5 | F3: 109.1 | G3: 113 | H3: 103.6 | I3: 103.4 | J3: 102.3 | K3: 102.9 | L3: 105.8 | M3: 105.1 | N3: 101.8 | O3: 105.1 | P3: 107.9 | Q3: 105.9 | R3: 105.2 | S3: 105.9 | T3: 105 | U3: 105.8 | V3: 100.3 | W3: 105.4 | X3: 104.8 | Y3: 104.1 | Z3: 103.2 | AA3: 102.9 | AB3: 103.5 | AC3: 104.3 | AD3: 103.7 | AE3: 104 | AF3: =SUM(E3:R3) -> 1481.6 | AG3: =SUM(S3:U3) -> 316.7 | AH3: =SUM(V3:X3) -> 310.5 | AI3: =SUM(Y3,AC3) -> 208.4 | AJ3: =SUM(Z3) -> 103.2 | AK3: =SUM(AA3) -> 102.9 | AL3: =SUM(AB3) -> 103.5
A4: Rural+Urban | B4: 2013 | C4: January | D4: =B4 & " - " & C4 -> 2013 - January | E4: 108.4 | F4: 107.3 | G4: 110 | H4: 104.4 | I4: 105.1 | J4: 103.2 | K4: 102.2 | L4: 106 | M4: 106.2 | N4: 102.7 | O4: 104.9 | P4: 107.3 | Q4: 105.6 | R4: 105.1 | S4: 106.3 | T4: 105.5 | U4: 106.2 | V4: 100.3 | W4: 105.5 | X4: 104.8 | Y4: 104 | Z4: 103.2 | AA4: 103.1 | AB4: 103.6 | AC4: 104.5 | AD4: 103.9 | AE4: 104.6 | AF4: =SUM(E4:R4) -> 1478.4 | AG4: =SUM(S4:U4) -> 318 | AH4: =SUM(V4:X4) -> 310.6 | AI4: =SUM(Y4,AC4) -> 208.5 | AJ4: =SUM(Z4) -> 103.2 | AK4: =SUM(AA4) -> 103.1 | AL4: =SUM(AB4) -> 103.6
A5: Rural | B5: 2013 | C5: February | D5: =B5 & " - " & C5 -> 2013 - February | E5: 109.2 | F5: 108.7 | G5: 110.2 | H5: 105.4 | I5: 106.7 | J5: 104 | K5: 102.4 | L5: 105.9 | M5: 105.7 | N5: 103.1 | O5: 105.1 | P5: 107.7 | Q5: 106.3 | R5: 105.6 | S5: 107.1 | T5: 106.3 | U5: 107 | V5: NA | W5: 106.2 | X5: 105.2 | Y5: 104.4 | Z5: 103.9 | AA5: 104 | AB5: 104.1 | AC5: 104.6 | AD5: 104.4 | AE5: 105.8 | AF5: =SUM(E5:R5) -> 1486 | AG5: =SUM(S5:U5) -> 320.4 | AH5: =SUM(V5:X5) -> 211.4 | AI5: =SUM(Y5,AC5) -> 209 | AJ5: =SUM(Z5) -> 103.9 | AK5: =SUM(AA5) -> 104 | AL5: =SUM(AB5) -> 104.1
A6: Urban | B6: 2013 | C6: February | D6: =B6 & " - " & C6 -> 2013 - February | E6: 112.9 | F6: 112.9 | G6: 116.9 | H6: 104 | I6: 103.5 | J6: 103.1 | K6: 104.9 | L6: 104.1 | M6: 103.8 | N6: 102.3 | O6: 106 | P6: 109 | Q6: 107.2 | R6: 106 | S6: 106.6 | T6: 105.5 | U6: 106.4 | V6: 100.4 | W6: 105.7 | X6: 105.2 | Y6: 104.7 | Z6: 104.4 | AA6: 103.3 | AB6: 103.7 | AC6: 104.3 | AD6: 104.3 | AE6: 104.7 | AF6: =SUM(E6:R6) -> 1496.6 | AG6: =SUM(S6:U6) -> 318.5 | AH6: =SUM(V6:X6) -> 311.3 | AI6: =SUM(Y6,AC6) -> 209 | AJ6: =SUM(Z6) -> 104.4 | AK6: =SUM(AA6) -> 103.3 | AL6: =SUM(AB6) -> 103.7
A7: Rural+Urban | B7: 2013 | C7: February | D7: =B7 & " - " & C7 -> 2013 - February | E7: 110.4 | F7: 110.2 | G7: 112.8 | H7: 104.9 | I7: 105.5 | J7: 103.6 | K7: 103.2 | L7: 105.3 | M7: 105.1 | N7: 102.8 | O7: 105.5 | P7: 108.3 | Q7: 106.6 | R7: 105.7 | S7: 106.9 | T7: 106 | U7: 106.8 | V7: 100.4 | W7: 106 | X7: 105.2 | Y7: 104.5 | Z7: 104.2 | AA7: 103.6 | AB7: 103.9 | AC7: 104.5 | AD7: 104.4 | AE7: 105.3 | AF7: =SUM(E7:R7) -> 1489.9 | AG7: =SUM(S7:U7) -> 319.7 | AH7: =SUM(V7:X7) -> 311.6 | AI7: =SUM(Y7,AC7) -> 209 | AJ7: =SUM(Z7) -> 104.2 | AK7: =SUM(AA7) -> 103.6 | AL7: =SUM(AB7) -> 103.9
A8: Rural | B8: 2013 | C8: March | D8: =B8 & " - " & C8 -> 2013 - March | E8: 110.2 | F8: 108.8 | G8: 109.9 | H8: 105.6 | I8: 106.2 | J8: 105.7 | K8: 101.4 | L8: 105.7 | M8: 105 | N8: 103.3 | O8: 105.6 | P8: 108.2 | Q8: 106.6 | R8: 106.5 | S8: 107.6 | T8: 106.8 | U8: 107.5 | V8: NA | W8: 106.1 | X8: 105.6 | Y8: 104.7 | Z8: 104.6 | AA8: 104 | AB8: 104.3 | AC8: 104.3 | AD8: 104.6 | AE8: 106 | AF8: =SUM(E8:R8) -> 1488.7 | AG8: =SUM(S8:U8) -> 321.9 | AH8: =SUM(V8:X8) -> 211.7 | AI8: =SUM(Y8,AC8) -> 209 | AJ8: =SUM(Z8) -> 104.6 | AK8: =SUM(AA8) -> 104 | AL8: =SUM(AB8) -> 104.3
A9: Urban | B9: 2013 | C9: March | D9: =B9 & " - " & C9 -> 2013 - March | E9: 113.9 | F9: 111.4 | G9: 113.2 | H9: 104.3 | I9: 102.7 | J9: 104.9 | K9: 103.8 | L9: 103.5 | M9: 102.6 | N9: 102.4 | O9: 107 | P9: 109.8 | Q9: 107.3 | R9: 106.8 | S9: 107.2 | T9: 106 | U9: 107 | V9: 100.4 | W9: 106 | X9: 105.7 | Y9: 105.2 | Z9: 105.5 | AA9: 103.5 | AB9: 103.8 | AC9: 104.2 | AD9: 104.9 | AE9: 105 | AF9: =SUM(E9:R9) -> 1493.6 | AG9: =SUM(S9:U9) -> 320.2 | AH9: =SUM(V9:X9) -> 312.1 | AI9: =SUM(Y9,AC9) -> 209.4 | AJ9: =SUM(Z9) -> 105.5 | AK9: =SUM(AA9) -> 103.5 | AL9: =SUM(AB9) -> 103.8
A10: Rural+Urban | B10: 2013 | C10: March | D10: =B10 & " - " & C10 -> 2013 - March | E10: 111.4 | F10: 109.7 | G10: 111.2 | H10: 105.1 | I10: 104.9 | J10: 105.3 | K10: 102.2 | L10: 105 | M10: 104.2 | N10: 103 | O10: 106.2 | P10: 108.9 | Q10: 106.9 | R10: 106.6 | S10: 107.4 | T10: 106.5 | U10: 107.3 | V10: 100.4 | W10: 106.1 | X10: 105.6 | Y10: 104.9 | Z10: 105.1 | AA10: 103.7 | AB10: 104 | AC10: 104.3 | AD10: 104.7 | AE10: 105.5 | AF10: =SUM(E10:R10) -> 1490.6 | AG10: =SUM(S10:U10) -> 321.2 | AH10: =SUM(V10:X10) -> 312.1 | AI10: =SUM(Y10,AC10) -> 209.2 | AJ10: =SUM(Z10) -> 105.1 | AK10: =SUM(AA10) -> 103.7 | AL10: =SUM(AB10) -> 104
A11: Rural | B11: 2013 | C11: April | D11: =B11 & " - " & C11 -> 2013 - April | E11: 110.2 | F11: 109.5 | G11: 106.9 | H11: 106.3 | I11: 105.7 | J11: 108.3 | K11: 103.4 | L11: 105.7 | M11: 104.2 | N11: 103.2 | O11: 106.5 | P11: 108.8 | Q11: 107.1 | R11: 107.1 | S11: 108.1 | T11: 107.4 | U11: 108 | V11: NA | W11: 106.5 | X11: 106.1 | Y11: 105.1 | Z11: 104.4 | AA11: 104.5 | AB11: 104.8 | AC11: 102.7 | AD11: 104.6 | AE11: 106.4 | AF11: =SUM(E11:R11) -> 1492.9 | AG11: =SUM(S11:U11) -> 323.5 | AH11: =SUM(V11:X11) -> 212.6 | AI11: =SUM(Y11,AC11) -> 207.8 | AJ11: =SUM(Z11) -> 104.4 | AK11: =SUM(AA11) -> 104.5 | AL11: =SUM(AB11) -> 104.8
A12: Urban | B12: 2013 | C12: April | D12: =B12 & " - " & C12 -> 2013 - April | E12: 114.6 | F12: 113.4 | G12: 106 | H12: 104.7 | I12: 102.1 | J12: 109.5 | K12: 109.7 | L12: 104.6 | M12: 102 | N12: 103.5 | O12: 108.2 | P12: 110.6 | Q12: 108.8 | R12: 108.5 | S12: 107.9 | T12: 106.4 | U12: 107.7 | V12: 100.5 | W12: 106.4 | X12: 106.5 | Y12: 105.7 | Z12: 105 | AA12: 104 | AB12: 105.2 | AC12: 103.2 | AD12: 105.1 | AE12: 105.7 | AF12: =SUM(E12:R12) -> 1506.2 | AG12: =SUM(S12:U12) -> 322 | AH12: =SUM(V12:X12) -> 313.4 | AI12: =SUM(Y12,AC12) -> 208.9 | AJ12: =SUM(Z12) -> 105 | AK12: =SUM(AA12) -> 104 | AL12: =SUM(AB12) -> 105.2
A13: Rural+Urban | B13: 2013 | C13: April | D13: =B13 & " - " & C13 -> 2013 - April | E13: 111.6 | F13: 110.9 | G13: 106.6 | H13: 105.7 | I13: 104.4 | J13: 108.9 | K13: 105.5 | L13: 105.3 | M13: 103.5 | N13: 103.3 | O13: 107.2 | P13: 109.6 | Q13: 107.7 | R13: 107.5 | S13: 108 | T13: 107 | U13: 107.9 | V13: 100.5 | W13: 106.5 | X13: 106.3 | Y13: 105.3 | Z13: 104.7 | AA13: 104.2 | AB13: 105 | AC13: 102.9 | AD13: 104.8 | AE13: 106.1 | AF13: =SUM(E13:R13) -> 1497.7 | AG13: =SUM(S13:U13) -> 322.9 | AH13: =SUM(V13:X13) -> 313.3 | AI13: =SUM(Y13,AC13) -> 208.2 | AJ13: =SUM(Z13) -> 104.7 | AK13: =SUM(AA13) -> 104.2 | AL13: =SUM(AB13) -> 105
A14: Rural | B14: 2013 | C14: May | D14: =B14 & " - " & C14 -> 2013 - May | E14: 110.9 | F14: 109.8 | G14: 105.9 | H14: 107.5 | I14: 105.3 | J14: 108.1 | K14: 107.3 | L14: 106.1 | M14: 103.7 | N14: 104 | O14: 107.4 | P14: 109.9 | Q14: 108.1 | R14: 108.1 | S14: 108.8 | T14: 107.9 | U14: 108.6 | V14: NA | W14: 107.5 | X14: 106.8 | Y14: 105.7 | Z14: 104.1 | AA14: 105 | AB14: 105.5 | AC14: 102.1 | AD14: 104.8 | AE14: 107.2 | AF14: =SUM(E14:R14) -> 1502.1 | AG14: =SUM(S14:U14) -> 325.3 | AH14: =SUM(V14:X14) -> 214.3 | AI14: =SUM(Y14,AC14) -> 207.8 | AJ14: =SUM(Z14) -> 104.1 | AK14: =SUM(AA14) -> 105 | AL14: =SUM(AB14) -> 105.5
A15: Urban | B15: 2013 | C15: May | D15: =B15 & " - " & C15 -> 2013 - May | E15: 115.4 | F15: 114.2 | G15: 102.7 | H15: 105.5 | I15: 101.5 | J15: 110.6 | K15: 123.7 | L15: 105.2 | M15: 101.9 | N15: 105 | O15: 109.1 | P15: 111.3 | Q15: 111.1 | R15: 109.8 | S15: 108.5 | T15: 106.7 | U15: 108.3 | V15: 100.5 | W15: 107.2 | X15: 107.1 | Y15: 106.2 | Z15: 103.9 | AA15: 104.6 | AB15: 105.7 | AC15: 102.6 | AD15: 104.9 | AE15: 106.6 | AF15: =SUM(E15:R15) -> 1527 | AG15: =SUM(S15:U15) -> 323.5 | AH15: =SUM(V15:X15) -> 314.8 | AI15: =SUM(Y15,AC15) -> 208.8 | AJ15: =SUM(Z15) -> 103.9 | AK15: =SUM(AA15) -> 104.6 | AL15: =SUM(AB15) -> 105.7
A16: Rural+Urban | B16: 2013 | C16: May | D16: =B16 & " - " & C16 -> 2013 - May | E16: 112.3 | F16: 111.3 | G16: 104.7 | H16: 106.8 | I16: 103.9 | J16: 109.3 | K16: 112.9 | L16: 105.8 | M16: 103.1 | N16: 104.3 | O16: 108.1 | P16: 110.5 | Q16: 109.2 | R16: 108.6 | S16: 108.7 | T16: 107.4 | U16: 108.5 | V16: 100.5 | W16: 107.4 | X16: 106.9 | Y16: 105.9 | Z16: 104 | AA16: 104.8 | AB16: 105.6 | AC16: 102.3 | AD16: 104.8 | AE16: 106.9 | AF16: =SUM(E16:R16) -> 1510.8 | AG16: =SUM(S16:U16) -> 324.6 | AH16: =SUM(V16:X16) -> 314.8 | AI16: =SUM(Y16,AC16) -> 208.2 | AJ16: =SUM(Z16) -> 104 | AK16: =SUM(AA16) -> 104.8 | AL16: =SUM(AB16) -> 105.6
A17: Rural | B17: 2013 | C17: June | D17: =B17 & " - " & C17 -> 2013 - June | E17: 112.3 | F17: 112.1 | G17: 108.1 | H17: 108.3 | I17: 105.9 | J17: 109.2 | K17: 118 | L17: 106.8 | M17: 104.1 | N17: 105.4 | O17: 108.2 | P17: 111 | Q17: 110.6 | R17: 109 | S17: 109.7 | T17: 108.8 | U17: 109.5 | V17: NA | W17: 108.5 | X17: 107.5 | Y17: 106.3 | Z17: 105 | AA17: 105.6 | AB17: 106.5 | AC17: 102.5 | AD17: 105.5 | AE17: 108.9 | AF17: =SUM(E17:R17) -> 1529 | AG17: =SUM(S17:U17) -> 328 | AH17: =SUM(V17:X17) -> 216 | AI17: =SUM(Y17,AC17) -> 208.8 | AJ17: =SUM(Z17) -> 105 | AK17: =SUM(AA17) -> 105.6 | AL17: =SUM(AB17) -> 106.5
A18: Urban | B18: 2013 | C18: June | D18: =B18 & " - " & C18 -> 2013 - June | E18: 117 | F18: 120.1 | G18: 112.5 | H18: 107.3 | I18: 101.3 | J18: 112.4 | K18: 143.6 | L18: 105.4 | M18: 101.4 | N18: 106.4 | O18: 110 | P18: 112.2 | Q18: 115 | R18: 110.9 | S18: 109.2 | T18: 107.2 | U18: 108.9 | V18: 106.6 | W18: 108 | X18: 107.7 | Y18: 106.5 | Z18: 105.2 | AA18: 105.2 | AB18: 108.1 | AC18: 103.3 | AD18: 106.1 | AE18: 109.7 | AF18: =SUM(E18:R18) -> 1575.5 | AG18: =SUM(S18:U18) -> 325.3 | AH18: =SUM(V18:X18) -> 322.3 | AI18: =SUM(Y18,AC18) -> 209.8 | AJ18: =SUM(Z18) -> 105.2 | AK18: =SUM(AA18) -> 105.2 | AL18: =SUM(AB18) -> 108.1
A19: Rural+Urban | B19: 2013 | C19: June | D19: =B19 & " - " & C19 -> 2013 - June | E19: 113.8 | F19: 114.9 | G19: 109.8 | H19: 107.9 | I19: 104.2 | J19: 110.7 | K19: 126.7 | L19: 106.3 | M19: 103.2 | N19: 105.7 | O19: 109 | P19: 111.6 | Q19: 112.2 | R19: 109.5 | S19: 109.5 | T19: 108.1 | U19: 109.3 | V19: 106.6 | W19: 108.3 | X19: 107.6 | Y19: 106.4 | Z19: 105.1 | AA19: 105.4 | AB19: 107.4 | AC19: 102.8 | AD19: 105.8 | AE19: 109.3 | AF19: =SUM(E19:R19) -> 1545.5 | AG19: =SUM(S19:U19) -> 326.9 | AH19: =SUM(V19:X19) -> 322.5 | AI19: =SUM(Y19,AC19) -> 209.2 | AJ19: =SUM(Z19) -> 105.1 | AK19: =SUM(AA19) -> 105.4 | AL19: =SUM(AB19) -> 107.4
A20: Rural | B20: 2013 | C20: July | D20: =B20 & " - " & C20 -> 2013 - July | E20: 113.4 | F20: 114.9 | G20: 110.5 | H20: 109.3 | I20: 106.2 | J20: 110.3 | K20: 129.2 | L20: 107.1 | M20: 104.3 | N20: 106.4 | O20: 109.1 | P20: 112.1 | Q20: 113.1 | R20: 109.8 | S20: 110.5 | T20: 109.5 | U20: 110.3 | V20: NA | W20: 109.5 | X20: 108.3 | Y20: 106.9 | Z20: 106.8 | AA20: 106.4 | AB20: 107.8 | AC20: 102.5 | AD20: 106.5 | AE20: 110.7 | AF20: =SUM(E20:R20) -> 1555.7 | AG20: =SUM(S20:U20) -> 330.3 | AH20: =SUM(V20:X20) -> 217.8 | AI20: =SUM(Y20,AC20) -> 209.4 | AJ20: =SUM(Z20) -> 106.8 | AK20: =SUM(AA20) -> 106.4 | AL20: =SUM(AB20) -> 107.8
A21: Urban | B21: 2013 | C21: July | D21: =B21 & " - " & C21 -> 2013 - July | E21: 117.8 | F21: 119.2 | G21: 114 | H21: 108.3 | I21: 101.1 | J21: 113.2 | K21: 160.9 | L21: 105.1 | M21: 101.3 | N21: 107.5 | O21: 110.4 | P21: 113.1 | Q21: 117.5 | R21: 111.7 | S21: 109.8 | T21: 107.8 | U21: 109.5 | V21: 107.7 | W21: 108.6 | X21: 108.1 | Y21: 107.1 | Z21: 107.3 | AA21: 105.9 | AB21: 110.1 | AC21: 103.2 | AD21: 107.3 | AE21: 111.4 | AF21: =SUM(E21:R21) -> 1601.1 | AG21: =SUM(S21:U21) -> 327.1 | AH21: =SUM(V21:X21) -> 324.4 | AI21: =SUM(Y21,AC21) -> 210.3 | AJ21: =SUM(Z21) -> 107.3 | AK21: =SUM(AA21) -> 105.9 | AL21: =SUM(AB21) -> 110.1
A22: Rural+Urban | B22: 2013 | C22: July | D22: =B22 & " - " & C22 -> 2013 - July | E22: 114.8 | F22: 116.4 | G22: 111.9 | H22: 108.9 | I22: 104.3 | J22: 111.7 | K22: 140 | L22: 106.4 | M22: 103.3 | N22: 106.8 | O22: 109.6 | P22: 112.6 | Q22: 114.7 | R22: 110.3 | S22: 110.2 | T22: 108.8 | U22: 110 | V22: 107.7 | W22: 109.2 | X22: 108.2 | Y22: 107 | Z22: 107.1 | AA22: 106.1 | AB22: 109.1 | AC22: 102.8 | AD22: 106.9 | AE22: 111 | AF22: =SUM(E22:R22) -> 1571.7 | AG22: =SUM(S22:U22) -> 329 | AH22: =SUM(V22:X22) -> 325.1 | AI22: =SUM(Y22,AC22) -> 209.8 | AJ22: =SUM(Z22) -> 107.1 | AK22: =SUM(AA22) -> 106.1 | AL22: =SUM(AB22) -> 109.1
A23: Rural | B23: 2013 | C23: August | D23: =B23 & " - " & C23 -> 2013 - August | E23: 114.3 | F23: 115.4 | G23: 111.1 | H23: 110 | I23: 106.4 | J23: 110.8 | K23: 138.9 | L23: 107.4 | M23: 104.1 | N23: 106.9 | O23: 109.7 | P23: 112.6 | Q23: 114.9 | R23: 110.7 | S23: 111.3 | T23: 110.2 | U23: 111.1 | V23: NA | W23: 109.9 | X23: 108.7 | Y23: 107.5 | Z23: 107.8 | AA23: 106.8 | AB23: 108.7 | AC23: 105 | AD23: 107.5 | AE23: 112.1 | AF23: =SUM(E23:R23) -> 1573.2 | AG23: =SUM(S23:U23) -> 332.6 | AH23: =SUM(V23:X23) -> 218.6 | AI23: =SUM(Y23,AC23) -> 212.5 | AJ23: =SUM(Z23) -> 107.8 | AK23: =SUM(AA23) -> 106.8 | AL23: =SUM(AB23) -> 108.7
A24: Urban | B24: 2013 | C24: August | D24: =B24 & " - " & C24 -> 2013 - August | E24: 118.3 | F24: 120.4 | G24: 112.7 | H24: 108.9 | I24: 101.1 | J24: 108.7 | K24: 177 | L24: 104.7 | M24: 101 | N24: 108.5 | O24: 110.9 | P24: 114.3 | Q24: 119.6 | R24: 112.4 | S24: 110.6 | T24: 108.3 | U24: 110.2 | V24: 108.9 | W24: 109.3 | X24: 108.7 | Y24: 107.6 | Z24: 108.1 | AA24: 106.5 | AB24: 110.8 | AC24: 106 | AD24: 108.3 | AE24: 112.7 | AF24: =SUM(E24:R24) -> 1618.5 | AG24: =SUM(S24:U24) -> 329.1 | AH24: =SUM(V24:X24) -> 326.9 | AI24: =SUM(Y24,AC24) -> 213.6 | AJ24: =SUM(Z24) -> 108.1 | AK24: =SUM(AA24) -> 106.5 | AL24: =SUM(AB24) -> 110.8
A25: Rural+Urban | B25: 2013 | C25: August | D25: =B25 & " - " & C25 -> 2013 - August | E25: 115.6 | F25: 117.2 | G25: 111.7 | H25: 109.6 | I25: 104.5 | J25: 109.8 | K25: 151.8 | L25: 106.5 | M25: 103.1 | N25: 107.4 | O25: 110.2 | P25: 113.4 | Q25: 116.6 | R25: 111.2 | S25: 111 | T25: 109.4 | U25: 110.7 | V25: 108.9 | W25: 109.7 | X25: 108.7 | Y25: 107.5 | Z25: 108 | AA25: 106.6 | AB25: 109.9 | AC25: 105.4 | AD25: 107.9 | AE25: 112.4 | AF25: =SUM(E25:R25) -> 1588.6 | AG25: =SUM(S25:U25) -> 331.1 | AH25: =SUM(V25:X25) -> 327.3 | AI25: =SUM(Y25,AC25) -> 212.9 | AJ25: =SUM(Z25) -> 108 | AK25: =SUM(AA25) -> 106.6 | AL25: =SUM(AB25) -> 109.9
A26: Rural | B26: 2013 | C26: September | D26: =B26 & " - " & C26 -> 2013 - September | E26: 115.4 | F26: 115.7 | G26: 111.7 | H26: 111 | I26: 107.4 | J26: 110.9 | K26: 154 | L26: 108.1 | M26: 104.2 | N26: 107.9 | O26: 110.4 | P26: 114 | Q26: 117.8 | R26: 111.7 | S26: 112.7 | T26: 111.4 | U26: 112.5 | V26: NA | W26: 111.1 | X26: 109.6 | Y26: 108.3 | Z26: 109.3 | AA26: 107.7 | AB26: 109.8 | AC26: 106.7 | AD26: 108.7 | AE26: 114.2 | AF26: =SUM(E26:R26) -> 1600.2 | AG26: =SUM(S26:U26) -> 336.6 | AH26: =SUM(V26:X26) -> 220.7 | AI26: =SUM(Y26,AC26) -> 215 | AJ26: =SUM(Z26) -> 109.3 | AK26: =SUM(AA26) -> 107.7 | AL26: =SUM(AB26) -> 109.8
A27: Urban | B27: 2013 | C27: September | D27: =B27 & " - " & C27 -> 2013 - September | E27: 118.6 | F27: 119.1 | G27: 113.2 | H27: 109.6 | I27: 101.7 | J27: 103.2 | K27: 174.3 | L27: 105.1 | M27: 100.8 | N27: 109.1 | O27: 111.1 | P27: 115.4 | Q27: 119.2 | R27: 112.9 | S27: 111.4 | T27: 109 | U27: 111.1 | V27: 109.7 | W27: 109.5 | X27: 109.6 | Y27: 107.9 | Z27: 110.4 | AA27: 107.4 | AB27: 111.2 | AC27: 106.9 | AD27: 109.4 | AE27: 113.2 | AF27: =SUM(E27:R27) -> 1613.3 | AG27: =SUM(S27:U27) -> 331.5 | AH27: =SUM(V27:X27) -> 328.8 | AI27: =SUM(Y27,AC27) -> 214.8 | AJ27: =SUM(Z27) -> 110.4 | AK27: =SUM(AA27) -> 107.4 | AL27: =SUM(AB27) -> 111.2
A28: Rural+Urban | B28: 2013 | C28: September | D28: =B28 & " - " & C28 -> 2013 - September | E28: 116.4 | F28: 116.9 | G28: 112.3 | H28: 110.5 | I28: 105.3 | J28: 107.3 | K28: 160.9 | L28: 107.1 | M28: 103.1 | N28: 108.3 | O28: 110.7 | P28: 114.6 | Q28: 118.3 | R28: 112 | S28: 112.2 | T28: 110.4 | U28: 111.9 | V28: 109.7 | W28: 110.5 | X28: 109.6 | Y28: 108.1 | Z28: 109.9 | AA28: 107.5 | AB28: 110.6 | AC28: 106.8 | AD28: 109 | AE28: 113.7 | AF28: =SUM(E28:R28) -> 1603.7 | AG28: =SUM(S28:U28) -> 334.5 | AH28: =SUM(V28:X28) -> 329.8 | AI28: =SUM(Y28,AC28) -> 214.9 | AJ28: =SUM(Z28) -> 109.9 | AK28: =SUM(AA28) -> 107.5 | AL28: =SUM(AB28) -> 110.6
A29: Rural | B29: 2013 | C29: October | D29: =B29 & " - " & C29 -> 2013 - October | E29: 116.3 | F29: 115.4 | G29: 112.6 | H29: 111.7 | I29: 107.7 | J29: 113.2 | K29: 164.9 | L29: 108.3 | M29: 103.9 | N29: 108.2 | O29: 111.1 | P29: 114.9 | Q29: 119.8 | R29: 112.2 | S29: 113.6 | T29: 112.3 | U29: 113.4 | V29: NA | W29: 111.6 | X29: 110.4 | Y29: 108.9 | Z29: 109.3 | AA29: 108.3 | AB29: 110.2 | AC29: 107.5 | AD29: 109.1 | AE29: 115.5 | AF29: =SUM(E29:R29) -> 1620.2 | AG29: =SUM(S29:U29) -> 339.3 | AH29: =SUM(V29:X29) -> 222 | AI29: =SUM(Y29,AC29) -> 216.4 | AJ29: =SUM(Z29) -> 109.3 | AK29: =SUM(AA29) -> 108.3 | AL29: =SUM(AB29) -> 110.2
A30: Urban | B30: 2013 | C30: October | D30: =B30 & " - " & C30 -> 2013 - October | E30: 118.9 | F30: 118.1 | G30: 114.5 | H30: 110.4 | I30: 102.3 | J30: 106.2 | K30: 183.5 | L30: 105.3 | M30: 100.2 | N30: 109.6 | O30: 111.4 | P30: 116 | Q30: 120.8 | R30: 113.5 | S30: 112.5 | T30: 109.7 | U30: 112 | V30: 110.5 | W30: 109.7 | X30: 110.2 | Y30: 108.2 | Z30: 109.7 | AA30: 108 | AB30: 111.3 | AC30: 107.3 | AD30: 109.4 | AE30: 114 | AF30: =SUM(E30:R30) -> 1630.7 | AG30: =SUM(S30:U30) -> 334.2 | AH30: =SUM(V30:X30) -> 330.4 | AI30: =SUM(Y30,AC30) -> 215.5 | AJ30: =SUM(Z30) -> 109.7 | AK30: =SUM(AA30) -> 108 | AL30: =SUM(AB30) -> 111.3
A31: Rural+Urban | B31: 2013 | C31: October | D31: =B31 & " - " & C31 -> 2013 - October | E31: 117.1 | F31: 116.3 | G31: 113.3 | H31: 111.2 | I31: 105.7 | J31: 109.9 | K31: 171.2 | L31: 107.3 | M31: 102.7 | N31: 108.7 | O31: 111.2 | P31: 115.4 | Q31: 120.2 | R31: 112.5 | S31: 113.2 | T31: 111.2 | U31: 112.8 | V31: 110.5 | W31: 110.9 | X31: 110.3 | Y31: 108.6 | Z31: 109.5 | AA31: 108.1 | AB31: 110.8 | AC31: 107.4 | AD31: 109.2 | AE31: 114.8 | AF31: =SUM(E31:R31) -> 1622.7 | AG31: =SUM(S31:U31) -> 337.2 | AH31: =SUM(V31:X31) -> 331.7 | AI31: =SUM(Y31,AC31) -> 216 | AJ31: =SUM(Z31) -> 109.5 | AK31: =SUM(AA31) -> 108.1 | AL31: =SUM(AB31) -> 110.8
A32: Rural | B32: 2013 | C32: November | D32: =B32 & " - " & C32 -> 2013 - November | E32: 117.3 | F32: 114.9 | G32: 116.2 | H32: 112.8 | I32: 108.9 | J32: 116.6 | K32: 178.1 | L32: 109.1 | M32: 103.6 | N32: 109 | O32: 111.8 | P32: 116 | Q32: 122.5 | R32: 112.8 | S32: 114.6 | T32: 113.1 | U32: 114.4 | V32: NA | W32: 112.6 | X32: 111.3 | Y32: 109.7 | Z32: 109.6 | AA32: 108.7 | AB32: 111 | AC32: 108.2 | AD32: 109.8 | AE32: 117.4 | AF32: =SUM(E32:R32) -> 1649.6 | AG32: =SUM(S32:U32) -> 342.1 | AH32: =SUM(V32:X32) -> 223.9 | AI32: =SUM(Y32,AC32) -> 217.9 | AJ32: =SUM(Z32) -> 109.6 | AK32: =SUM(AA32) -> 108.7 | AL32: =SUM(AB32) -> 111
A33: Urban | B33: 2013 | C33: November | D33: =B33 & " - " & C33 -> 2013 - November | E33: 119.8 | F33: 116.3 | G33: 122.6 | H33: 112 | I33: 103.2 | J33: 110 | K33: 192.8 | L33: 106.3 | M33: 99.5 | N33: 110.3 | O33: 111.8 | P33: 117.1 | Q33: 122.9 | R33: 114.1 | S33: 113.5 | T33: 110.3 | U33: 113 | V33: 111.1 | W33: 110 | X33: 110.9 | Y33: 108.6 | Z33: 109.5 | AA33: 108.5 | AB33: 111.3 | AC33: 107.9 | AD33: 109.6 | AE33: 115 | AF33: =SUM(E33:R33) -> 1658.7 | AG33: =SUM(S33:U33) -> 336.8 | AH33: =SUM(V33:X33) -> 332 | AI33: =SUM(Y33,AC33) -> 216.5 | AJ33: =SUM(Z33) -> 109.5 | AK33: =SUM(AA33) -> 108.5 | AL33: =SUM(AB33) -> 111.3
A34: Rural+Urban | B34: 2013 | C34: November | D34: =B34 & " - " & C34 -> 2013 - November | E34: 118.1 | F34: 115.4 | G34: 118.7 | H34: 112.5 | I34: 106.8 | J34: 113.5 | K34: 183.1 | L34: 108.2 | M34: 102.2 | N34: 109.4 | O34: 111.8 | P34: 116.5 | Q34: 122.6 | R34: 113.1 | S34: 114.2 | T34: 111.9 | U34: 113.8 | V34: 111.1 | W34: 111.6 | X34: 111.1 | Y34: 109.3 | Z34: 109.5 | AA34: 108.6 | AB34: 111.2 | AC34: 108.1 | AD34: 109.7 | AE34: 116.3 | AF34: =SUM(E34:R34) -> 1651.9 | AG34: =SUM(S34:U34) -> 339.9 | AH34: =SUM(V34:X34) -> 333.8 | AI34: =SUM(Y34,AC34) -> 217.4 | AJ34: =SUM(Z34) -> 109.5 | AK34: =SUM(AA34) -> 108.6 | AL34: =SUM(AB34) -> 111.2
A35: Rural | B35: 2013 | C35: December | D35: =B35 & " - " & C35 -> 2013 - December | E35: 118.4 | F35: 115.9 | G35: 120.4 | H35: 113.8 | I35: 109.5 | J35: 115.5 | K35: 145.7 | L35: 109.5 | M35: 102.9 | N35: 109.8 | O35: 112.1 | P35: 116.8 | Q35: 118.7 | R35: 113.6 | S35: 115.8 | T35: 114 | U35: 115.5 | V35: NA | W35: 112.8 | X35: 112.1 | Y35: 110.1 | Z35: 109.9 | AA35: 109.2 | AB35: 111.6 | AC35: 108.1 | AD35: 110.1 | AE35: 115.5 | AF35: =SUM(E35:R35) -> 1622.6 | AG35: =SUM(S35:U35) -> 345.3 | AH35: =SUM(V35:X35) -> 224.9 | AI35: =SUM(Y35,AC35) -> 218.2 | AJ35: =SUM(Z35) -> 109.9 | AK35: =SUM(AA35) -> 109.2 | AL35: =SUM(AB35) -> 111.6
A36: Urban | B36: 2013 | C36: December | D36: =B36 & " - " & C36 -> 2013 - December | E36: 120.5 | F36: 118.1 | G36: 128.5 | H36: 112.8 | I36: 103.4 | J36: 110.7 | K36: 144.8 | L36: 107.1 | M36: 98.6 | N36: 111.9 | O36: 112.1 | P36: 118.1 | Q36: 117.8 | R36: 115 | S36: 114.2 | T36: 110.9 | U36: 113.7 | V36: 110.7 | W36: 110.4 | X36: 111.3 | Y36: 109 | Z36: 109.7 | AA36: 108.9 | AB36: 111.4 | AC36: 107.7 | AD36: 109.8 | AE36: 113.3 | AF36: =SUM(E36:R36) -> 1619.4 | AG36: =SUM(S36:U36) -> 338.8 | AH36: =SUM(V36:X36) -> 332.4 | AI36: =SUM(Y36,AC36) -> 216.7 | AJ36: =SUM(Z36) -> 109.7 | AK36: =SUM(AA36) -> 108.9 | AL36: =SUM(AB36) -> 111.4
A37: Rural+Urban | B37: 2013 | C37: December | D37: =B37 & " - " & C37 -> 2013 - December | E37: 119.1 | F37: 116.7 | G37: 123.5 | H37: 113.4 | I37: 107.3 | J37: 113.3 | K37: 145.4 | L37: 108.7 | M37: 101.5 | N37: 110.5 | O37: 112.1 | P37: 117.4 | Q37: 118.4 | R37: 114 | S37: 115.2 | T37: 112.7 | U37: 114.8 | V37: 110.7 | W37: 111.9 | X37: 111.7 | Y37: 109.7 | Z37: 109.8 | AA37: 109 | AB37: 111.5 | AC37: 107.9 | AD37: 110 | AE37: 114.5 | AF37: =SUM(E37:R37) -> 1621.3 | AG37: =SUM(S37:U37) -> 342.7 | AH37: =SUM(V37:X37) -> 334.3 | AI37: =SUM(Y37,AC37) -> 217.6 | AJ37: =SUM(Z37) -> 109.8 | AK37: =SUM(AA37) -> 109 | AL37: =SUM(AB37) -> 111.5
A38: Rural | B38: 2014 | C38: January | D38: =B38 & " - " & C38 -> 2014 - January | E38: 118.9 | F38: 117.1 | G38: 120.5 | H38: 114.4 | I38: 109 | J38: 115.5 | K38: 123.9 | L38: 109.6 | M38: 101.8 | N38: 110.2 | O38: 112.4 | P38: 117.3 | Q38: 116 | R38: 114 | S38: 116.5 | T38: 114.5 | U38: 116.2 | V38: NA | W38: 113 | X38: 112.6 | Y38: 110.6 | Z38: 110.5 | AA38: 109.6 | AB38: 111.8 | AC38: 108.3 | AD38: 110.6 | AE38: 114.2 | AF38: =SUM(E38:R38) -> 1600.6 | AG38: =SUM(S38:U38) -> 347.2 | AH38: =SUM(V38:X38) -> 225.6 | AI38: =SUM(Y38,AC38) -> 218.9 | AJ38: =SUM(Z38) -> 110.5 | AK38: =SUM(AA38) -> 109.6 | AL38: =SUM(AB38) -> 111.8
A39: Urban | B39: 2014 | C39: January | D39: =B39 & " - " & C39 -> 2014 - January | E39: 121.2 | F39: 122 | G39: 129.9 | H39: 113.6 | I39: 102.9 | J39: 112.1 | K39: 118.9 | L39: 107.5 | M39: 96.9 | N39: 112.7 | O39: 112.1 | P39: 119 | Q39: 115.5 | R39: 115.7 | S39: 114.8 | T39: 111.3 | U39: 114.3 | V39: 111.6 | W39: 111 | X39: 111.9 | Y39: 109.7 | Z39: 110.8 | AA39: 109.8 | AB39: 111.5 | AC39: 108 | AD39: 110.5 | AE39: 112.9 | AF39: =SUM(E39:R39) -> 1600 | AG39: =SUM(S39:U39) -> 340.4 | AH39: =SUM(V39:X39) -> 334.5 | AI39: =SUM(Y39,AC39) -> 217.7 | AJ39: =SUM(Z39) -> 110.8 | AK39: =SUM(AA39) -> 109.8 | AL39: =SUM(AB39) -> 111.5
A40: Rural+Urban | B40: 2014 | C40: January | D40: =B40 & " - " & C40 -> 2014 - January | E40: 119.6 | F40: 118.8 | G40: 124.1 | H40: 114.1 | I40: 106.8 | J40: 113.9 | K40: 122.2 | L40: 108.9 | M40: 100.2 | N40: 111 | O40: 112.3 | P40: 118.1 | Q40: 115.8 | R40: 114.5 | S40: 115.8 | T40: 113.2 | U40: 115.4 | V40: 111.6 | W40: 112.2 | X40: 112.3 | Y40: 110.3 | Z40: 110.7 | AA40: 109.7 | AB40: 111.6 | AC40: 108.2 | AD40: 110.6 | AE40: 113.6 | AF40: =SUM(E40:R40) -> 1600.3 | AG40: =SUM(S40:U40) -> 344.4 | AH40: =SUM(V40:X40) -> 336.1 | AI40: =SUM(Y40,AC40) -> 218.5 | AJ40: =SUM(Z40) -> 110.7 | AK40: =SUM(AA40) -> 109.7 | AL40: =SUM(AB40) -> 111.6
...

Sheet Transpose
D1: 2013 | E1: 2013 | F1: 2013 | G1: 2013 | H1: 2013 | I1: 2013 | J1: 2013 | K1: 2013 | L1: 2013 | M1: 2013 | N1: 2013 | O1: 2013 | P1: 2014 | Q1: 2014 | R1: 2014 | S1: 2014 | T1: 2014 | U1: 2014 | V1: 2014 | W1: 2014 | X1: 2014 | Y1: 2014 | Z1: 2014 | AA1: 2014 | AB1: 2015 | AC1: 2015 | AD1: 2015 | AE1: 2015 | AF1: 2015 | AG1: 2015 | AH1: 2015 | AI1: 2015 | AJ1: 2015 | AK1: 2015 | AL1: 2015 | AM1: 2015 | AN1: 2016 | AO1: 2016 | AP1: 2016 | AQ1: 2016 | AR1: 2016 | AS1: 2016 | AT1: 2016 | AU1: 2016 | AV1: 2016 | AW1: 2016 | AX1: 2016 | AY1: 2016 | AZ1: 2017 | BA1: 2017 | BB1: 2017 | BC1: 2017 | BD1: 2017 | BE1: 2017 | BF1: 2017 | BG1: 2017 | BH1: 2017 | BI1: 2017 | BJ1: 2017 | BK1: 2017 | BL1: 2018 | BM1: 2018 | BN1: 2018 | BO1: 2018 | BP1: 2018 | BQ1: 2018 | BR1: 2018 | BS1: 2018 | BT1: 2018 | BU1: 2018 | BV1: 2018 | BW1: 2018 | BX1: 2019 | BY1: 2019 | BZ1: 2019 | CA1: 2019 | CB1: 2019 | CC1: 2019 | CD1: 2019 | CE1: 2019 | CF1: 2019 | CG1: 2019 | CH1: 2019 | CI1: 2020 | CJ1: 2020 | CK1: 2020 | CL1: 2020 | CM1: 2020 | CN1: 2020 | CO1: 2020 | CP1: 2020 | CQ1: 2020 | CR1: 2020 | CS1: 2020 | CT1: 2020 | CU1: 2021 | CV1: 2021 | CW1: 2021 | CX1: 2021 | CY1: 2021 | CZ1: 2021 | DA1: 2021 | DB1: 2021 | DC1: 2021 | DD1: 2021 | DE1: 2021 | DF1: 2021 | DG1: 2022 | DH1: 2022 | DI1: 2022 | DJ1: 2022 | DK1: 2022 | DL1: 2022 | DM1: 2022 | DN1: 2022 | DO1: 2022 | DP1: 2022 | DQ1: 2022 | DR1: 2022 | DS1: 2023 | DT1: 2023 | DU1: 2023 | DV1: 2023 | DW1: 2023
A2: Sector | B2: Broader Cat | C2: Category | D2: January | E2: February | F2: March | G2: April | H2: May | I2: June | J2: July | K2: August | L2: September | M2: October | N2: November | O2: December | P2: January | Q2: February | R2: March | S2: April | T2: May | U2: June | V2: July | W2: August | X2: September | Y2: October | Z2: November | AA2: December | AB2: January | AC2: February | AD2: March | AE2: April | AF2: May | AG2: June | AH2: July | AI2: August | AJ2: September | AK2: October | AL2: November | AM2: December | AN2: January | AO2: February | AP2: March | AQ2: April | AR2: May | AS2: June | AT2: July | AU2: August | AV2: September | AW2: October | AX2: November | AY2: December | AZ2: January | BA2: February | BB2: March | BC2: April | BD2: May | BE2: June | BF2: July | BG2: August | BH2: September | BI2: October | BJ2: November | BK2: December | BL2: January | BM2: February | BN2: March | BO2: April | BP2: May | BQ2: June | BR2: July | BS2: August | BT2: September | BU2: October | BV2: November | BW2: December | BX2: January | BY2: February | BZ2: March | CA2: May | CB2: June | CC2: July | CD2: August | CE2: September | CF2: October | CG2: November | CH2: December | CI2: January | CJ2: February | CK2: March | CL2: April | CM2: May | CN2: June | CO2: July | CP2: August | CQ2: September | CR2: October | CS2: November | CT2: December | CU2: January | CV2: February | CW2: March | CX2: April | CY2: May | CZ2: June | DA2: July | DB2: August | DC2: September | DD2: October | DE2: November | DF2: December | DG2: January | DH2: February | DI2: March | DJ2: April | DK2: May | DL2: June | DM2: July | DN2: August | DO2: September | DP2: October | DQ2: November | DR2: December | DS2: January | DT2: February | DU2: March | DV2: April | DW2: May
A3: Rural | B3: =VLOOKUP(C3,'Broader Categories'!$A$1:$B$28,2,FALSE) -> Food | C3: Cereals and products | D3: 107.5 | E3: 109.2 | F3: 110.2 | G3: 110.2 | H3: 110.9 | I3: 112.3 | J3: 113.4 | K3: 114.3 | L3: 115.4 | M3: 116.3 | N3: 117.3 | O3: 118.4 | P3: 118.9 | Q3: 119.4 | R3: 120.1 | S3: 120.2 | T3: 120.3 | U3: 120.7 | V3: 121.7 | W3: 121.8 | X3: 122.3 | Y3: 122.6 | Z3: 122.7 | AA3: 122.4 | AB3: 123.1 | AC3: 123.4 | AD3: 123.3 | AE3: 123.3 | AF3: 123.5 | AG3: 124.1 | AH3: 124 | AI3: 124.7 | AJ3: 125.1 | AK3: 125.6 | AL3: 126.1 | AM3: 126.3 | AN3: 126.8 | AO3: 127.1 | AP3: 127.3 | AQ3: 127.4 | AR3: 127.6 | AS3: 128.6 | AT3: 129.3 | AU3: 130.1 | AV3: 130.8 | AW3: 131.3 | AX3: 132 | AY3: 132.6 | AZ3: 133.1 | BA3: 133.3 | BB3: 133.6 | BC3: 133.2 | BD3: 133.1 | BE3: 133.5 | BF3: 134 | BG3: 134.8 | BH3: 135.2 | BI3: 135.9 | BJ3: 136.3 | BK3: 136.4 | BL3: 136.6 | BM3: 136.4 | BN3: 136.8 | BO3: 137.1 | BP3: 137.4 | BQ3: 137.6 | BR3: 138.4 | BS3: 139.2 | BT3: 139.4 | BU3: 139.3 | BV3: 137.1 | BW3: 137.1 | BX3: 136.6 | BY3: 136.8 | BZ3: 136.9 | CA3: 137.4 | CB3: 137.8 | CC3: 138.4 | CD3: 139.2 | CE3: 140.1 | CF3: 141 | CG3: 141.8 | CH3: 142.8 | CI3: 143.7 | CJ3: 144.2 | CK3: 144.4 | CL3: 147.2 | CM3: NA | CN3: 148.2 | CO3: 148.2 | CP3: 147.6 | CQ3: 146.9 | CR3: 146 | CS3: 145.4 | CT3: 144.6 | CU3: 143.4 | CV3: 142.8 | CW3: 142.5 | CX3: 142.7 | CY3: 145.1 | CZ3: 145.6 | DA3: 145.1 | DB3: 144.9 | DC3: 145.4 | DD3: 146.1 | DE3: 146.9 | DF3: 147.4 | DG3: 148.3 | DH3: 148.8 | DI3: 150.2 | DJ3: 151.8 | DK3: 152.9 | DL3: 153.8 | DM3: 155.2 | DN3: 159.5 | DO3: 162.9 | DP3: 164.7 | DQ3: 166.9 | DR3: 168.8 | DS3: 174 | DT3: 174.2 | DU3: 174.3 | DV3: 173.3 | DW3: 173.2
A4: Rural | B4: =VLOOKUP(C4,'Broader Categories'!$A$1:$B$28,2,FALSE) -> Food | C4: Meat and fish | D4: 106.3 | E4: 108.7 | F4: 108.8 | G4: 109.5 | H4: 109.8 | I4: 112.1 | J4: 114.9 | K4: 115.4 | L4: 115.7 | M4: 115.4 | N4: 114.9 | O4: 115.9 | P4: 117.1 | Q4: 117.7 | R4: 118.1 | S4: 118.9 | T4: 120.2 | U4: 121.6 | V4: 122.5 | W4: 122.8 | X4: 122.4 | Y4: 122.5 | Z4: 122.6 | AA4: 122.4 | AB4: 123.1 | AC4: 124.4 | AD4: 124.7 | AE4: 125.5 | AF4: 127.1 | AG4: 130.4 | AH4: 131.5 | AI4: 131.3 | AJ4: 131.1 | AK4: 130.4 | AL4: 130.6 | AM4: 131.3 | AN4: 133.2 | AO4: 133.7 | AP4: 134.4 | AQ4: 135.4 | AR4: 137.5 | AS4: 138.6 | AT4: 139.5 | AU4: 138.8 | AV4: 138.2 | AW4: 137.6 | AX4: 137.4 | AY4: 137.3 | AZ4: 137.8 | BA4: 138.3 | BB4: 138.8 | BC4: 138.7 | BD4: 140.3 | BE4: 143.7 | BF4: 144.2 | BG4: 143.1 | BH4: 142 | BI4: 141.9 | BJ4: 142.5 | BK4: 143.7 | BL4: 144.4 | BM4: 143.7 | BN4: 143.8 | BO4: 144.5 | BP4: 145.7 | BQ4: 148.1 | BR4: 149.3 | BS4: 148.8 | BT4: 147.2 | BU4: 147.6 | BV4: 150.8 | BW4: 151.9 | BX4: 152.5 | BY4: 153 | BZ4: 154.1 | CA4: 159.5 | CB4: 163.5 | CC4: 164 | CD4: 161.9 | CE4: 161.9 | CF4: 161.6 | CG4: 163.7 | CH4: 165.3 | CI4: 167.3 | CJ4: 167.5 | CK4: 166.8 | CL4: NA | CM4: NA | CN4: 190.3 | CO4: 190.3 | CP4: 187.2 | CQ4: 183.9 | CR4: 186.3 | CS4: 188.6 | CT4: 188.5 | CU4: 187.5 | CV4: 184 | CW4: 189.4 | CX4: 195.5 | CY4: 198.5 | CZ4: 200.1 | DA4: 204.5 | DB4: 202.3 | DC4: 202.1 | DD4: 202.5 | DE4: 199.8 | DF4: 197 | DG4: 196.9 | DH4: 198.1 | DI4: 208 | DJ4: 209.7 | DK4: 214.7 | DL4: 217.2 | DM4: 210.8 | DN4: 204.1 | DO4: 206.7 | DP4: 208.8 | DQ4: 207.2 | DR4: 206.9 | DS4: 208.3 | DT4: 205.2 | DU4: 205.2 | DV4: 206.9 | DW4: 211.5
A5: Rural | B5: =VLOOKUP(C5,'Broader Categories'!$A$1:$B$28,2,FALSE) -> Food | C5: Egg | D5: 108.1 | E5: 110.2 | F5: 109.9 | G5: 106.9 | H5: 105.9 | I5: 108.1 | J5: 110.5 | K5: 111.1 | L5: 111.7 | M5: 112.6 | N5: 116.2 | O5: 120.4 | P5: 120.5 | Q5: 121.2 | R5: 120.7 | S5: 118.1 | T5: 116.9 | U5: 116.1 | V5: 117.7 | W5: 117.8 | X5: 117.8 | Y5: 118.3 | Z5: 119.9 | AA5: 121.8 | AB5: 122.1 | AC5: 122.1 | AD5: 118.9 | AE5: 117.2 | AF5: 117.3 | AG5: 122.1 | AH5: 122 | AI5: 121.3 | AJ5: 120.7 | AK5: 120.8 | AL5: 121.7 | AM5: 123.3 | AN5: 126.5 | AO5: 127.7 | AP5: 125.1 | AQ5: 123.4 | AR5: 124.4 | AS5: 126.6 | AT5: 129.6 | AU5: 130.3 | AV5: 130.5 | AW5: 130.1 | AX5: 130.6 | AY5: 131.6 | AZ5: 131.9 | BA5: 129.3 | BB5: 128.8 | BC5: 127.1 | BD5: 126.8 | BE5: 128 | BF5: 129.8 | BG5: 130 | BH5: 130.5 | BI5: 131 | BJ5: 140.5 | BK5: 144.8 | BL5: 143.8 | BM5: 140.6 | BN5: 140 | BO5: 135.9 | BP5: 135.5 | BQ5: 136.7 | BR5: 139.3 | BS5: 139.1 | BT5: 136.6 | BU5: 134.6 | BV5: 136.7 | BW5: 137.4 | BX5: 138.2 | BY5: 139.1 | BZ5: 138.7 | CA5: 134.5 | CB5: 136.2 | CC5: 138.4 | CD5: 137.1 | CE5: 138.3 | CF5: 141.2 | CG5: 143.8 | CH5: 149.5 | CI5: 153.5 | CJ5: 150.9 | CK5: 147.6 | CL5: 146.9 | CM5: NA | CN5: 149.4 | CO5: 149.4 | CP5: 148.4 | CQ5: 149.5 | CR5: 159.2 | CS5: 171.6 | CT5: 173.4 | CU5: 173.4 | CV5: 168 | CW5: 163.2 | CX5: 163.4 | CY5: 168.6 | CZ5: 179.3 | DA5: 180.4 | DB5: 176.5 | DC5: 172 | DD5: 170.1 | DE5: 171.5 | DF5: 176.5 | DG5: 178 | DH5: 175.5 | DI5: 167.9 | DJ5: 164.5 | DK5: 161.4 | DL5: 169.6 | DM5: 174.3 | DN5: 168.3 | DO5: 169 | DP5: 170.3 | DQ5: 180.2 | DR5: 189.1 | DS5: 192.9 | DT5: 173.9 | DU5: 173.9 | DV5: 167.9 | DW5: 171
A6: Rural | B6: =VLOOKUP(C6,'Broader Categories'!$A$1:$B$28,2,FALSE) -> Food | C6: Milk and products | D6: 104.9 | E6: 105.4 | F6: 105.6 | G6: 106.3 | H6: 107.5 | I6: 108.3 | J6: 109.3 | K6: 110 | L6: 111 | M6: 111.7 | N6: 112.8 | O6: 113.8 | P6: 114.4 | Q6: 115 | R6: 116.1 | S6: 117 | T6: 118 | U6: 119.3 | V6: 120.6 | W6: 121.9 | X6: 122.7 | Y6: 123.2 | Z6: 124 | AA6: 124.2 | AB6: 124.9 | AC6: 125.8 | AD6: 126 | AE6: 126.8 | AF6: 127.7 | AG6: 128.7 | AH6: 128.7 | AI6: 128.8 | AJ6: 129.2 | AK6: 129.4 | AL6: 129.5 | AM6: 129.8 | AN6: 130.3 | AO6: 130.7 | AP6: 130.5 | AQ6: 131.3 | AR6: 132.4 | AS6: 133.6 | AT6: 134.5 | AU6: 135.3 | AV6: 135.5 | AW6: 136 | AX6: 136.2 | AY6: 136.3 | AZ6: 136.7 | BA6: 137.2 | BB6: 137.2 | BC6: 137.7 | BD6: 138.2 | BE6: 138.6 | BF6: 139 | BG6: 139.4 | BH6: 140.2 | BI6: 141.5 | BJ6: 141.5 | BK6: 141.9 | BL6: 142 | BM6: 141.5 | BN6: 142 | BO6: 142.4 | BP6: 142.9 | BQ6: 143.2 | BR6: 143.4 | BS6: 143.5 | BT6: 143.7 | BU6: 141.9 | BV6: 141.9 | BW6: 142.4 | BX6: 142.4 | BY6: 142.5 | BZ6: 142.5 | CA6: 142.6 | CB6: 143.2 | CC6: 143.9 | CD6: 144.6 | CE6: 145.7 | CF6: 146.5 | CG6: 147.1 | CH6: 148.7 | CI6: 150.5 | CJ6: 150.9 | CK6: 151.7 | CL6: 155.6 | CM6: NA | CN6: 153.3 | CO6: 153.3 | CP6: 153.3 | CQ6: 153.4 | CR6: 153.6 | CS6: 153.8 | CT6: 154 | CU6: 154 | CV6: 154.4 | CW6: 154.5 | CX6: 155 | CY6: 155.8 | CZ6: 156.1 | DA6: 157.1 | DB6: 157.5 | DC6: 158 | DD6: 158.4 | DE6: 159.1 | DF6: 159.8 | DG6: 160.5 | DH6: 160.7 | DI6: 162 | DJ6: 163.8 | DK6: 164.6 | DL6: 165.4 | DM6: 166.3 | DN6: 167.9 | DO6: 169.5 | DP6: 170.9 | DQ6: 172.3 | DR6: 173.4 | DS6: 174.3 | DT6: 177 | DU6: 177 | DV6: 178.2 | DW6: 179.6
A7: Rural | B7: =VLOOKUP(C7,'Broader Categories'!$A$1:$B$28,2,FALSE) -> Food | C7: Oils and fats | D7: 106.1 | E7: 106.7 | F7: 106.2 | G7: 105.7 | H7: 105.3 | I7: 105.9 | J7: 106.2 | K7: 106.4 | L7: 107.4 | M7: 107.7 | N7: 108.9 | O7: 109.5 | P7: 109 | Q7: 109 | R7: 109.3 | S7: 109.7 | T7: 110.1 | U7: 110.3 | V7: 110.4 | W7: 110.6 | X7: 110.4 | Y7: 110.5 | Z7: 110.5 | AA7: 110.2 | AB7: 111 | AC7: 111.5 | AD7: 111.8 | AE7: 111.9 | AF7: 112.5 | AG7: 114.1 | AH7: 113.5 | AI7: 114 | AJ7: 114.7 | AK7: 115.8 | AL7: 117.8 | AM7: 118.3 | AN7: 118.9 | AO7: 118.5 | AP7: 118.3 | AQ7: 118.2 | AR7: 118.2 | AS7: 118.6 | AT7: 119.5 | AU7: 119.9 | AV7: 120.2 | AW7: 120.8 | AX7: 121.1 | AY7: 121.6 | AZ7: 122 | BA7: 122.1 | BB7: 121.6 | BC7: 121.3 | BD7: 120.8 | BE7: 120.9 | BF7: 120.9 | BG7: 120.5 | BH7: 120.7 | BI7: 121.4 | BJ7: 121.6 | BK7: 123.1 | BL7: 123.2 | BM7: 122.9 | BN7: 123.2 | BO7: 123.5 | BP7: 123.6 | BQ7: 124 | BR7: 124.1 | BS7: 125 | BT7: 124.6 | BU7: 123.5 | BV7: 122.8 | BW7: 124.2 | BX7: 123.9 | BY7: 124.1 | BZ7: 124.1 | CA7: 124 | CB7: 124.3 | CC7: 124.4 | CD7: 124.7 | CE7: 125.1 | CF7: 125.6 | CG7: 126 | CH7: 127.5 | CI7: 132 | CJ7: 133.7 | CK7: 133.3 | CL7: 137.1 | CM7: NA | CN7: 138.2 | CO7: 138.2 | CP7: 139.8 | CQ7: 140.4 | CR7: 142.6 | CS7: 145.4 | CT7: 150 | CU7: 154.8 | CV7: 163 | CW7: 168.2 | CX7: 175.2 | CY7: 184.4 | CZ7: 190.4 | DA7: 188.7 | DB7: 190.9 | DC7: 195.5 | DD7: 198.8 | DE7: 198.4 | DF7: 195.8 | DG7: 192.6 | DH7: 192.6 | DI7: 203.1 | DJ7: 207.4 | DK7: 209.9 | DL7: 208.1 | DM7: 202.2 | DN7: 198.1 | DO7: 194.1 | DP7: 191.6 | DQ7: 194 | DR7: 193.9 | DS7: 192.6 | DT7: 183.4 | DU7: 183.3 | DV7: 178.5 | DW7: 173.3
A8: Rural | B8: =VLOOKUP(C8,'Broader Categories'!$A$1:$B$28,2,FALSE) -> Food | C8: Fruits | D8: 103.9 | E8: 104 | F8: 105.7 | G8: 108.3 | H8: 108.1 | I8: 109.2 | J8: 110.3 | K8: 110.8 | L8: 110.9 | M8: 113.2 | N8: 116.6 | O8: 115.5 | P8: 115.5 | Q8: 116.6 | R8: 119.6 | S8: 125.5 | T8: 126.3 | U8: 125.8 | V8: 129.1 | W8: 129.7 | X8: 129.8 | Y8: 128.9 | Z8: 128.8 | AA8: 128.6 | AB8: 130.4 | AC8: 129.4 | AD8: 130.9 | AE8: 134.2 | AF8: 134.1 | AG8: 133.2 | AH8: 133.3 | AI8: 134.2 | AJ8: 132.3 | AK8: 133.2 | AL8: 132.1 | AM8: 131.6 | AN8: 131.6 | AO8: 130.4 | AP8: 131.7 | AQ8: 138.1 | AR8: 138.1 | AS8: 137.4 | AT8: 138.5 | AU8: 140.2 | AV8: 139.2 | AW8: 138.4 | AX8: 136.9 | AY8: 135.6 | AZ8: 136 | BA8: 138.7 | BB8: 139.7 | BC8: 141.8 | BD8: 140.2 | BE8: 140.9 | BF8: 143.9 | BG8: 148 | BH8: 147.8 | BI8: 146.7 | BJ8: 147.3 | BK8: 147.2 | BL8: 147.9 | BM8: 149.4 | BN8: 152.9 | BO8: 156.4 | BP8: 157.5 | BQ8: 154.1 | BR8: 153.3 | BS8: 154.4 | BT8: 150.1 | BU8: 144.5 | BV8: 143.9 | BW8: 140.2 | BX8: 135.5 | BY8: 135.8 | BZ8: 136.1 | CA8: 143.7 | CB8: 143.3 | CC8: 146.4 | CD8: 145.5 | CE8: 143.8 | CF8: 145.7 | CG8: 146.2 | CH8: 144.3 | CI8: 142.2 | CJ8: 140.7 | CK8: 141.8 | CL8: 147.3 | CM8: NA | CN8: 143.2 | CO8: 143.2 | CP8: 146.9 | CQ8: 147 | CR8: 147.2 | CS8: 146.5 | CT8: 145.9 | CU8: 147 | CV8: 147.8 | CW8: 150.5 | CX8: 160.6 | CY8: 162.3 | CZ8: 158.6 | DA8: 157.7 | DB8: 155.7 | DC8: 152.7 | DD8: 152.6 | DE8: 153.2 | DF8: 152 | DG8: 151.2 | DH8: 151.4 | DI8: 155.9 | DJ8: 169.7 | DK8: 168 | DL8: 165.8 | DM8: 169.6 | DN8: 169.2 | DO8: 164.1 | DP8: 162.2 | DQ8: 159.1 | DR8: 156.7 | DS8: 156.3 | DT8: 167.2 | DU8: 167.2 | DV8: 173.7 | DW8: 169
A9: Rural | B9: =VLOOKUP(C9,'Broader Categories'!$A$1:$B$28,2,FALSE) -> Food | C9: Vegetables | D9: 101.9 | E9: 102.4 | F9: 101.4 | G9: 103.4 | H9: 107.3 | I9: 118 | J9: 129.2 | K9: 138.9 | L9: 154 | M9: 164.9 | N9: 178.1 | O9: 145.7 | P9: 123.9 | Q9: 116 | R9: 117.9 | S9: 120.5 | T9: 123.9 | U9: 129.3 | V9: 150.1 | W9: 161.1 | X9: 158.8 | Y9: 155.3 | Z9: 152 | AA9: 140.3 | AB9: 132.3 | AC9: 128.2 | AD9: 128 | AE9: 127.5 | AF9: 128.5 | AG9: 135.2 | AH9: 140.8 | AI9: 153.6 | AJ9: 158.9 | AK9: 157.7 | AL9: 155.2 | AM9: 145.5 | AN9: 140.1 | AO9: 130.9 | AP9: 130.7 | AQ9: 134.1 | AR9: 141.8 | AS9: 152.5 | AT9: 158.2 | AU9: 156.9 | AV9: 149.5 | AW9: 149.2 | AX9: 141.8 | AY9: 127.5 | AZ9: 119.8 | BA9: 119.1 | BB9: 119.7 | BC9: 121.5 | BD9: 123.8 | BE9: 128.8 | BF9: 151.5 | BG9: 162.9 | BH9: 154.5 | BI9: 157.1 | BJ9: 168 | BK9: 161 | BL9: 152.1 | BM9: 142.4 | BN9: 138 | BO9: 135.1 | BP9: 137.8 | BQ9: 143.5 | BR9: 154.2 | BS9: 156.3 | BT9: 149.4 | BU9: 147.6 | BV9: 147.5 | BW9: 136.6 | BX9: 131.7 | BY9: 128.7 | BZ9: 128.2 | CA9: 133.4 | CB9: 140.6 | CC9: 150.1 | CD9: 156.2 | CE9: 163.4 | CF9: 178.8 | CG9: 191.4 | CH9: 209.5 | CI9: 191.5 | CJ9: 165.1 | CK9: 152.3 | CL9: 162.7 | CM9: NA | CN9: 148.9 | CO9: 148.9 | CP9: 171 | CQ9: 178.8 | CR9: 200.6 | CS9: 222.2 | CT9: 225.2 | CU9: 187.8 | CV9: 149.7 | CW9: 141 | CX9: 135.1 | CY9: 138.4 | CZ9: 144.7 | DA9: 152.8 | DB9: 153.9 | DC9: 151.4 | DD9: 170.4 | DE9: 183.9 | DF9: 172.3 | DG9: 159.2 | DH9: 155.2 | DI9: 155.8 | DJ9: 153.6 | DK9: 160.4 | DL9: 167.3 | DM9: 168.6 | DN9: 173.1 | DO9: 176.9 | DP9: 184.8 | DQ9: 171.6 | DR9: 150.2 | DS9: 142.9 | DT9: 140.9 | DU9: 140.9 | DV9: 142.8 | DW9: 148.7
A10: Rural | B10: =VLOOKUP(C10,'Broader Categories'!$A$1:$B$28,2,FALSE) -> Food | C10: Pulses and products | D10: 106.1 | E10: 105.9 | F10: 105.7 | G10: 105.7 | H10: 106.1 | I10: 106.8 | J10: 107.1 | K10: 107.4 | L10: 108.1 | M10: 108.3 | N10: 109.1 | O10: 109.5 | P10: 109.6 | Q10: 109.8 | R10: 110.2 | S10: 111 | T10: 111.5 | U10: 112.2 | V10: 113.2 | W10: 114.1 | X10: 115 | Y10: 115.5 | Z10: 116.2 | AA10: 116.3 | AB10: 117.2 | AC10: 118.8 | AD10: 119.9 | AE10: 121.5 | AF10: 124.3 | AG10: 131.9 | AH10: 133.8 | AI10: 137.9 | AJ10: 142.1 | AK10: 154.2 | AL10: 160.8 | AM10: 162.1 | AN10: 163.8 | AO10: 162.8 | AP10: 161.2 | AQ10: 162.7 | AR10: 166 | AS10: 169.2 | AT10: 171.8 | AU10: 172.2 | AV10: 170.4 | AW10: 170.2 | AX10: 170 | AY10: 167.9 | AZ10: 161.7 | BA10: 156.9 | BB10: 148 | BC10: 144.5 | BD10: 141.8 | BE10: 140.2 | BF10: 138.1 | BG10: 137.4 | BH10: 137.1 | BI10: 136.4 | BJ10: 135.8 | BK10: 133.8 | BL10: 131.8 | BM10: 130.2 | BN10: 129.3 | BO10: 128.4 | BP10: 127.2 | BQ10: 126 | BR10: 126.4 | BS10: 126.8 | BT10: 125.4 | BU10: 121.4 | BV10: 121 | BW10: 120.9 | BX10: 121.3 | BY10: 121.5 | BZ10: 122.3 | CA10: 125.1 | CB10: 128.7 | CC10: 130.6 | CD10: 131.5 | CE10: 132.2 | CF10: 133.1 | CG10: 136.2 | CH10: 138.8 | CI10: 141.1 | CJ10: 141.8 | CK10: 141.8 | CL10: 150.2 | CM10: NA | CN10: 150.3 | CO10: 150.3 | CP10: 149.9 | CQ10: 149.3 | CR10: 150.3 | CS10: 155.9 | CT10: 159.5 | CU10: 159.5 | CV10: 158.3 | CW10: 159.2 | CX10: 161.1 | CY10: 165.1 | CZ10: 165.5 | DA10: 163.6 | DB10: 162.8 | DC10: 163.9 | DD10: 165.2 | DE10: 165.4 | DF10: 164.5 | DG10: 164 | DH10: 163.9 | DI10: 164.2 | DJ10: 165.1 | DK10: 165 | DL10: 164.6 | DM10: 164.4 | DN10: 167.1 | DO10: 169 | DP10: 169.7 | DQ10: 170.2 | DR10: 170.5 | DS10: 170.7 | DT10: 170.4 | DU10: 170.5 | DV10: 172.8 | DW10: 174.9
